<?xml version="1.0"?>
<robot name="rp_robot">
    
    <!-- TO CHECK INERTIA PROPERTIES RUN roslaunch robot_inertia_publisher robot_inertia_publisher.launch --> 

    <material name="grey">
        <color rgba="0.5 0.5 0.5 1"/>
    </material>
    <material name="blue">
        <color rgba="0.0 0.2 0.3 1"/>
    </material>
    <material name="red">
        <color rgba="0.5 0.1 0.2 1"/>
    </material>
    <material name="black">
        <color rgba="0.0 0.0 0.0 1"/>
    </material>

    <link name="L00">
        <visual>
            <origin xyz="0.0 0.0 2.0" rpy="0.0 0.0 0.0"/>
            <geometry>
                <mesh filename="package://tameshiwari/robots/rp_robot_description/meshes/Link_00.stl" scale="1 1 1"/>
            </geometry>
            <material name="grey"/>
        </visual>
        <collision>
            <origin xyz="0.0 0.0 2.0" rpy="0.0 0.0 0.0"/>
            <geometry>
                <mesh filename="package://tameshiwari/robots/rp_robot_description/meshes/Link_00.stl" scale="1 1 1"/>
            </geometry>
        </collision>
        <inertial>
            <origin xyz="-0.251674 0.0 1.121284" rpy="0.0 0.0 0.0"/>
            <mass value="456.291"/>
            <inertia ixx="1.976e+2" ixy="2.277e-15" ixz="-1.333e0" iyy="1.894e+2" iyz="1.030e-15" izz="1.041e+1"/>
        </inertial>
    </link>

    <joint name="J00" type="revolute">
        <origin xyz="0.0 0.0 2.0" rpy="0.0 1.5707 0.0"/>
        <parent link="L00"/>
        <child link="L01"/>
        <axis xyz="0.0 0.0 1.0"/>
        <limit effort="10000" velocity="0.5" lower="-1.3090" upper="4.4506"/> 
        <!-- enforcing joint limits from [-5*pi/12,17*pi/12], resulting in a deadzone of 30 degrees -->
    </joint>
    
    <transmission name="trans_J00">
        <type>transmission_interface/SimpleTransmission</type>
        <joint name="J00">
            <hardwareInterface>hardware_interface/EffortJointInterface</hardwareInterface>
        </joint>
        <actuator name="motor_J00">
             <hardwareInterface>hardware_interface/EffortJointInterface</hardwareInterface>
             <mechanicalReduction>1</mechanicalReduction>
        </actuator>
    </transmission>

    <link name="L01">
        <visual>
            <origin xyz="0.0 0.0 0.0" rpy="0.0 0.0 0.0"/>
            <geometry>
                <mesh filename="package://tameshiwari/robots/rp_robot_description/meshes/Link_01.stl" scale="1 1 1"/>
            </geometry>
            <material name="blue" />
        </visual>
        <collision>
            <origin xyz="0.0 0.0 0.0" rpy="0.0 0.0 0.0"/>
            <geometry>
                <mesh filename="package://tameshiwari/robots/rp_robot_description/meshes/Link_01.stl" scale="1 1 1"/>
            </geometry>
        </collision>
        <inertial>
            <origin xyz="0.516573 0.0 0.0" rpy="0.0 0.0 0.0"/>
            <mass value="54.677"/>
            <inertia ixx="5.494e-1" ixy="-3.832e-4" ixz="0.0" iyy="5.022e0" iyz="0.0" izz="5.035e0"/>
        </inertial>
    </link>

    <joint name="J01" type="prismatic">
        <origin xyz="0.57 0.0 0.0" rpy="0.0 1.5707 0.0"/>
        <parent link="L01"/>
        <child link="L02"/>
        <axis xyz="0.0 0.0 1.0"/>
        <limit lower="-0.37" upper="0.37" effort="1000.0" velocity="0.5"/>
    </joint>

    <transmission name="trans_J01">
        <type>transmission_interface/SimpleTransmission</type>
        <joint name="J01">
            <hardwareInterface>hardware_interface/EffortJointInterface</hardwareInterface>
        </joint>
        <actuator name="motor_J01">
             <hardwareInterface>hardware_interface/EffortJointInterface</hardwareInterface>
             <mechanicalReduction>1</mechanicalReduction>
        </actuator>
    </transmission>

    <link name="L02">
        <visual>
            <origin xyz="0.0 0.0 0.0" rpy="0.0 0.0 0.0"/>
            <geometry>
                <mesh filename="package://tameshiwari/robots/rp_robot_description/meshes/Link_02.stl" scale="1 1 1"/>
            </geometry>
            <material name="red" />
        </visual>
        <collision>
            <origin xyz="0.0 0.0 0.0" rpy="0.0 0.0 0.0"/>
            <geometry>
                <mesh filename="package://tameshiwari/robots/rp_robot_description/meshes/Link_02.stl" scale="1 1 1"/>
            </geometry>
        </collision>
        <inertial>
            <origin xyz="0.0 0.0 0.352179" rpy="0.0 0.0 0.0"/>
            <mass value="17.606"/>
            <inertia ixx="1.349" ixy="0.0" ixz="0.0" iyy="1.349" iyz="0.0" izz="2.816e-2"/>
        </inertial>
    </link>

    <joint name="J02" type="fixed">
        <origin xyz="0.0 0.0 0.875" rpy="0.0 0.0 0.0"/>
        <parent link="L02"/>
        <child link="EE"/>
    </joint>

    <link name="EE">
        <visual>
            <origin xyz="0.0 0.0 0.0" rpy="0.0 0.0 0.0"/>
            <geometry>
                <sphere radius="0.1"/>
            </geometry>
            <material name="black" />
        </visual>
        <collision>
            <origin xyz="0.0 0.0 0.0" rpy="0.0 0.0 0.0"/>
            <geometry>
                <sphere radius="0.1"/>
            </geometry>
        </collision>
        <inertial>
            <origin xyz="0.0 0.0 0.0" rpy="0.0 0.0 0.0"/>
            <mass value="1000"/>
            <inertia ixx="4.0" ixy="0.0" ixz="0.0" iyy="4.0" iyz="0.0" izz="4.0"/>
        </inertial>
    </link>

</robot>